Workbook

Sheet Overview
A1: Sheets | B1: Name of Sheets
A2: Sheet 1 | B2: Courier Company Invoice
A3: Sheet 2 | B3: Company X-Order Report
A4: Sheet 3 | B4: Company X-SKU Master
A5: Sheet 4 | B5: Company X-Pincode Zones
A6: Sheet 5 | B6: Courier Company -Rates
A7: Sheet 6 | B7: Columns as per Output Data 1
A8: Summary | B8: It is a summry table of overall work done

Sheet Sheet1
A1: AWB Code | B1: Order ID | C1: Charged Weight | D1: Warehouse Pincode | E1: Customer Pincode | F1: Zone | G1: Type of Shipment | H1: Billing Amount (Rs.)
A2: 1091117222124 | B2: 2001806232 | C2: 1.3 | D2: 121003 | E2: 507101 | F2: d | G2: Forward charges | H2: 135
A3: 1091117222194 | B3: 2001806273 | C3: 1 | D3: 121003 | E3: 486886 | F3: d | G3: Forward charges | H3: 90.2
A4: 1091117222931 | B4: 2001806408 | C4: 2.5 | D4: 121003 | E4: 532484 | F4: d | G4: Forward charges | H4: 224.6
A5: 1091117223244 | B5: 2001806458 | C5: 1 | D5: 121003 | E5: 143001 | F5: b | G5: Forward charges | H5: 61.3
A6: 1091117229345 | B6: 2001807012 | C6: 0.15 | D6: 121003 | E6: 515591 | F6: d | G6: Forward charges | H6: 45.4
A7: 1091117229555 | B7: 2001806686 | C7: 0.15 | D7: 121003 | E7: 326502 | F7: d | G7: Forward charges | H7: 45.4
A8: 1091117229776 | B8: 2001806885 | C8: 1 | D8: 121003 | E8: 208019 | F8: b | G8: Forward charges | H8: 61.3
A9: 1091117323112 | B9: 2001807058 | C9: 1.15 | D9: 121003 | E9: 140301 | F9: b | G9: Forward charges | H9: 89.6
A10: 1091117323812 | B10: 2001807186 | C10: 0.5 | D10: 121003 | E10: 396001 | F10: d | G10: Forward charges | H10: 45.4
A11: 1091117324206 | B11: 2001807290 | C11: 0.5 | D11: 121003 | E11: 711106 | F11: d | G11: Forward charges | H11: 45.4
A12: 1091117326612 | B12: 2001807814 | C12: 0.79 | D12: 121003 | E12: 284001 | F12: b | G12: Forward charges | H12: 61.3
A13: 1091117327172 | B13: 2001807931 | C13: 0.72 | D13: 121003 | E13: 441601 | F13: d | G13: Forward charges | H13: 90.2
... A125: 1091121846136 | B125: 2001811305 | C125: 0.5 | D125: 121003 | E125: 302020 | F125: d | G125: Forward charges | H125: 45.4

Sheet Sheet2
A1: ExternOrderNo | B1: SKU | C1: Order Qty
A2: 2001827036 | B2: 8904223818706 | C2: 1.00
A3: 2001827036 | B3: 8904223819093 | C3: 1.00
A4: 2001827036 | B4: 8904223819109 | C4: 1.00
A5: 2001827036 | B5: 8904223818430 | C5: 1.00
A6: 2001827036 | B6: 8904223819277 | C6: 1.00
A7: 2001827036 | B7: GIFTBOX202002 | C7: 1.00
A8: 2001827036 | B8: 8904223818638 | C8: 2.00
A9: 2001827036 | B9: SACHETS001 | C9: 1.00
A10: 2001825261 | B10: 8904223819024 | C10: 4.00
A11: 2001825261 | B11: 8904223819291 | C11: 4.00
A12: 2001825261 | B12: 8904223818638 | C12: 3.00
A13: 2001825261 | B13: 8904223818669 | C13: 1.00
A14: 2001825261 | B14: SACHETS001 | C14: 1.00
A15: 2001823564 | B15: 8904223819291 | C15: 2.00
A16: 2001823564 | B16: 8904223819031 | C16: 2.00
A17: 2001823564 | B17: 8904223819024 | C17: 2.00
A18: 2001822466 | B18: 8904223819468 | C18: 2.00
A19: 2001822466 | B19: 8904223819291 | C19: 8.00
A20: 2001821995 | B20: 8904223819130 | C20: 1.00
A21: 2001821995 | B21: 8904223818706 | C21: 1.00
A22: 2001821766 | B22: 8904223818591 | C22: 2.00
A23: 2001821750 | B23: 8904223818850 | C23: 1.00
A24: 2001821750 | B24: 8904223818430 | C24: 1.00
A25: 2001821750 | B25: 8904223819130 | C25: 1.00
A26: 2001821742 | B26: 8904223819468 | C26: 1.00
... A47: 2001819252 | B47: 8904223818706 | C47: 1.00
A48: 2001819252 | B48: SACHETS001 | C48: 1.00
A49: 2001818390 | B49: 8904223819147 | C49: 1.00
A50: 2001818390 | B50: 8904223818935 | C50: 4.00
A51: 2001818390 | B51: 8904223818683 | C51: 1.00
A52: 2001817160 | B52: 8904223818478 | C52: 1.00
A53: 2001817160 | B53: 8904223819284 | C53: 1.00
A54: 2001817093 | B54: 8904223816214 | C54: 1.00
A55: 2001817093 | B55: 8904223818874 | C55: 1.00
A56: 2001817093 | B56: 8904223819512 | C56: 1.00
A57: 2001817093 | B57: 8904223818881 | C57: 1.00
A58: 2001817093 | B58: 8904223819291 | C58: 2.00
A59: 2001817093 | B59: 8904223819031 | C59: 2.00
A60: 2001817093 | B60: 8904223819024 | C60: 2.00
...

Sheet Sheet3
A1: SKU | B1: Weight (g)
A2: 8904223815682 | B2: 210
A3: 8904223815859 | B3: 165
A4: 8904223815866 | B4: 113
A5: 8904223815873 | B5: 65
A6: 8904223816214 | B6: 120
A7: 8904223816665 | B7: 102
A8: 8904223817273 | B8: 65
A9: 8904223817334 | B9: 170
A10: 8904223817501 | B10: 350
A11: 8904223818430 | B11: 165
A12: 8904223818478 | B12: 350
A13: 8904223818553 | B13: 115
... A51: 8904223819437 | B51: 552
A52: GIFTBOX202001 | B52: 500
A53: GIFTBOX202004 | B53: 500
A54: GIFTBOX202002 | B54: 500
A55: 8904223819369 | B55: 170
A56: GIFTBOX202003 | B56: 500
A57: 8904223819123 | B57: 250
A58: GIFTBOX202002 | B58: 500
A59: 8904223819468 | B59: 240
A60: 8904223819260 | B60: 130
A61: 8904223819321 | B61: 600
A62: 8904223819338 | B62: 600
A63: 8904223819505 | B63: 210
A64: 8904223819499 | B64: 210
A65: 8904223819512 | B65: 210
A66: 8904223819543 | B66: 300
A67: SACHETS001 | B67: 10

Sheet Sheet4
A1: Warehouse Pincode | B1: Customer Pincode | C1: Zone
A2: 121003 | B2: 507101 | C2: d
A3: 121003 | B3: 486886 | C3: d
A4: 121003 | B4: 532484 | C4: d
A5: 121003 | B5: 143001 | C5: b
A6: 121003 | B6: 515591 | C6: d
A7: 121003 | B7: 326502 | C7: d
A8: 121003 | B8: 208019 | C8: b
A9: 121003 | B9: 140301 | C9: b
A10: 121003 | B10: 396001 | C10: d
A11: 121003 | B11: 711106 | C11: d
A12: 121003 | B12: 284001 | C12: b
A13: 121003 | B13: 441601 | C13: d
... A125: 121003 | B125: 302020 | C125: b

Sheet Sheet5
A1: fwd_a_fixed | B1: fwd_a_additional | C1: fwd_b_fixed | D1: fwd_b_additional | E1: fwd_c_fixed | F1: fwd_c_additional | G1: fwd_d_fixed | H1: fwd_d_additional | I1: fwd_e_fixed | J1: fwd_e_additional | K1: rto_a_fixed | L1: rto_a_additional | M1: rto_b_fixed | N1: rto_b_additional | O1: rto_c_fixed | P1: rto_c_additional | Q1: rto_d_fixed | R1: rto_d_additional | S1: rto_e_fixed | T1: rto_e_additional
A2: 29.5 | B2: 23.6 | C2: 33 | D2: 28.3 | E2: 40.1 | F2: 38.9 | G2: 45.4 | H2: 44.8 | I2: 56.6 | J2: 55.5 | K2: 13.6 | L2: 23.6 | M2: 20.5 | N2: 28.3 | O2: 31.9 | P2: 38.9 | Q2: 41.3 | R2: 44.8 | S2: 50.7 | T2: 55.5
C4: Zone | D4: fwd_fixed | E4: fwd_additional | F4: rto_fixed | G4: rto_additional
C5: a | F5: 13.6 | G5: 23.6
C6: b | D6: 33 | E6: 28.3 | F6: 20.5 | G6: 28.3
C7: c | D7: 40.1 | E7: 38.9 | F7: 31.9 | G7: 38.9
C8: d | D8: 45.4 | E8: 44.8 | F8: 41.3 | G8: 44.8
C9: e | D9: 56.6 | E9: 55.5 | F9: 50.7 | G9: 55.5

Sheet Sheet6
A1: Order ID | B1: AWB | C1: Total Weight as per X(Kg) | D1: Weight slab as per X(Kg) | E1: Total Weight as per Courier Company (KG) | F1: Weigt Slab charged by Courier Company(Kg) | G1: Delivery Zone as per X | H1: Delivery Zone Charged by Courier Company | I1: Charges Billed by Courier Company(Rs) | J1: Number of 0.5 Kg Slab | K1: Additonal Slab | L1: Forward Fixed Charge | M1: Forward Additonal Charge | N1: Forward Total | O1: RTO Fixed | P1: RTO Additional | Q1: RTO Total | R1: Expected Charge as per X | S1: Difference
A2: 2001806232 | B2: =_xlfn.XLOOKUP(A2,Sheet1!B:B,Sheet1!A:A) -> 1091117222124 | C2: {=SUMPRODUCT((Sheet2!$A$2:$A$1000=Sheet6!A2)*Sheet2!$C$2:$C$1000*IFERROR(VLOOKUP(Sheet2!$B$2:$B$1000,Sheet3!$A:$B,2,FALSE),0))/1000} -> 1.302 | D2: =CEILING(C2/0.5,1)*0.5 -> 1.5 | E2: =VLOOKUP(A2,Sheet1!B:C,2,FALSE) -> 1.3 | F2: =CEILING(E2/0.5,1)*0.5 -> 1.5 | G2: =VLOOKUP(Sheet4!B2,Sheet4!B:C,2,FALSE) -> d | H2: =VLOOKUP(A2,Sheet1!B:D,3,FALSE) -> 121003 | I2: =VLOOKUP(A2,Sheet1!B:H,7,FALSE) -> 135 | J2: =D2/0.5 -> 3 | K2: =MAX(J2-1,0) -> 2 | L2: =INDEX(Sheet5!$A$2:$T$2,MATCH("fwd_"&LOWER(G2)&"_fixed",Sheet5!$A$1:$T$1,0)) -> 45.4 | M2: =INDEX(Sheet5!$A$2:$Z$2,MATCH("fwd_"&LOWER(G2)&"_additional", Sheet5!$A$1:$Z$1, 0) ) -> 44.8 | N2: =L2+(K2*M2) -> 135 | O2: =INDEX( Sheet5!$A$2:$Z$2, MATCH("rto_"&LOWER(G2)&"_fixed", Sheet5!$A$1:$Z$1, 0) ) -> 41.3 | P2: =INDEX( Sheet5!$A$2:$Z$2, MATCH("rto_"&LOWER(G2)&"_additional", Sheet5!$A$1:$Z$1, 0) ) -> 44.8 | Q2: =O2+(K2*P2) -> 130.9 | R2: =N2+Q2 -> 265.9 | S2: =R2-I2 -> 130.9
A3: 2001806273 | B3: =_xlfn.XLOOKUP(A3,Sheet1!B:B,Sheet1!A:A) -> 1091117222194 | C3: {=SUMPRODUCT((Sheet2!$A$2:$A$1000=Sheet6!A3)*Sheet2!$C$2:$C$1000*IFERROR(VLOOKUP(Sheet2!$B$2:$B$1000,Sheet3!$A:$B,2,FALSE),0))/1000} -> 0.615 | D3: =CEILING(C3/0.5,1)*0.5 -> 1 | E3: =VLOOKUP(A3,Sheet1!B:C,2,FALSE) -> 1 | F3: =CEILING(E3/0.5,1)*0.5 -> 1 | G3: =VLOOKUP(Sheet4!B3,Sheet4!B:C,2,FALSE) -> d | H3: =VLOOKUP(A3,Sheet1!B:D,3,FALSE) -> 121003 | I3: =VLOOKUP(A3,Sheet1!B:H,7,FALSE) -> 90.2 | J3: =D3/0.5 -> 2 | K3: =MAX(J3-1,0) -> 1 | L3: =INDEX(Sheet5!$A$2:$T$2,MATCH("fwd_"&LOWER(G3)&"_fixed",Sheet5!$A$1:$T$1,0)) -> 45.4 | M3: =INDEX(Sheet5!$A$2:$Z$2,MATCH("fwd_"&LOWER(G3)&"_additional", Sheet5!$A$1:$Z$1, 0) ) -> 44.8 | N3: =L3+(K3*M3) -> 90.2 | O3: =INDEX( Sheet5!$A$2:$Z$2, MATCH("rto_"&LOWER(G3)&"_fixed", Sheet5!$A$1:$Z$1, 0) ) -> 41.3 | P3: =INDEX( Sheet5!$A$2:$Z$2, MATCH("rto_"&LOWER(G3)&"_additional", Sheet5!$A$1:$Z$1, 0) ) -> 44.8 | Q3: =O3+(K3*P3) -> 86.1 | R3: =N3+Q3 -> 176.3 | S3: =R3-I3 -> 86.1
A4: 2001806408 | B4: =_xlfn.XLOOKUP(A4,Sheet1!B:B,Sheet1!A:A) -> 1091117222931 | C4: {=SUMPRODUCT((Sheet2!$A$2:$A$1000=Sheet6!A4)*Sheet2!$C$2:$C$1000*IFERROR(VLOOKUP(Sheet2!$B$2:$B$1000,Sheet3!$A:$B,2,FALSE),0))/1000} -> 2.265 | D4: =CEILING(C4/0.5,1)*0.5 -> 2.5 | E4: =VLOOKUP(A4,Sheet1!B:C,2,FALSE) -> 2.5 | F4: =CEILING(E4/0.5,1)*0.5 -> 2.5 | G4: =VLOOKUP(Sheet4!B4,Sheet4!B:C,2,FALSE) -> d | H4: =VLOOKUP(A4,Sheet1!B:D,3,FALSE) -> 121003 | I4: =VLOOKUP(A4,Sheet1!B:H,7,FALSE) -> 224.6 | J4: =D4/0.5 -> 5 | K4: =MAX(J4-1,0) -> 4 | L4: =INDEX(Sheet5!$A$2:$T$2,MATCH("fwd_"&LOWER(G4)&"_fixed",Sheet5!$A$1:$T$1,0)) -> 45.4 | M4: =INDEX(Sheet5!$A$2:$Z$2,MATCH("fwd_"&LOWER(G4)&"_additional", Sheet5!$A$1:$Z$1, 0) ) -> 44.8 | N4: =L4+(K4*M4) -> 224.6 | O4: =INDEX( Sheet5!$A$2:$Z$2, MATCH("rto_"&LOWER(G4)&"_fixed", Sheet5!$A$1:$Z$1, 0) ) -> 41.3 | P4: =INDEX( Sheet5!$A$2:$Z$2, MATCH("rto_"&LOWER(G4)&"_additional", Sheet5!$A$1:$Z$1, 0) ) -> 44.8 | Q4: =O4+(K4*P4) -> 220.5 | R4: =N4+Q4 -> 445.1 | S4: =R4-I4 -> 220.5
A5: 2001806458 | B5: =_xlfn.XLOOKUP(A5,Sheet1!B:B,Sheet1!A:A) -> 1091117223244 | C5: {=SUMPRODUCT((Sheet2!$A$2:$A$1000=Sheet6!A5)*Sheet2!$C$2:$C$1000*IFERROR(VLOOKUP(Sheet2!$B$2:$B$1000,Sheet3!$A:$B,2,FALSE),0))/1000} -> 0.7 | D5: =CEILING(C5/0.5,1)*0.5 -> 1 | E5: =VLOOKUP(A5,Sheet1!B:C,2,FALSE) -> 1 | F5: =CEILING(E5/0.5,1)*0.5 -> 1 | G5: =VLOOKUP(Sheet4!B5,Sheet4!B:C,2,FALSE) -> b | H5: =VLOOKUP(A5,Sheet1!B:D,3,FALSE) -> 121003 | I5: =VLOOKUP(A5,Sheet1!B:H,7,FALSE) -> 61.3 | J5: =D5/0.5 -> 2 | K5: =MAX(J5-1,0) -> 1 | L5: =INDEX(Sheet5!$A$2:$T$2,MATCH("fwd_"&LOWER(G5)&"_fixed",Sheet5!$A$1:$T$1,0)) -> 33 | M5: =INDEX(Sheet5!$A$2:$Z$2,MATCH("fwd_"&LOWER(G5)&"_additional", Sheet5!$A$1:$Z$1, 0) ) -> 28.3 | N5: =L5+(K5*M5) -> 61.3 | O5: =INDEX( Sheet5!$A$2:$Z$2, MATCH("rto_"&LOWER(G5)&"_fixed", Sheet5!$A$1:$Z$1, 0) ) -> 20.5 | P5: =INDEX( Sheet5!$A$2:$Z$2, MATCH("rto_"&LOWER(G5)&"_additional", Sheet5!$A$1:$Z$1, 0) ) -> 28.3 | Q5: =O5+(K5*P5) -> 48.8 | R5: =N5+Q5 -> 110.1 | S5: =R5-I5 -> 48.8
A6: 2001807012 | B6: =_xlfn.XLOOKUP(A6,Sheet1!B:B,Sheet1!A:A) -> 1091117229345 | C6: {=SUMPRODUCT((Sheet2!$A$2:$A$1000=Sheet6!A6)*Sheet2!$C$2:$C$1000*IFERROR(VLOOKUP(Sheet2!$B$2:$B$1000,Sheet3!$A:$B,2,FALSE),0))/1000} -> 0.24 | D6: =CEILING(C6/0.5,1)*0.5 -> 0.5 | E6: =VLOOKUP(A6,Sheet1!B:C,2,FALSE) -> 0.15 | F6: =CEILING(E6/0.5,1)*0.5 -> 0.5 | G6: =VLOOKUP(Sheet4!B6,Sheet4!B:C,2,FALSE) -> d | H6: =VLOOKUP(A6,Sheet1!B:D,3,FALSE) -> 121003 | I6: =VLOOKUP(A6,Sheet1!B:H,7,FALSE) -> 45.4 | J6: =D6/0.5 -> 1 | K6: =MAX(J6-1,0) -> 0 | L6: =INDEX(Sheet5!$A$2:$T$2,MATCH("fwd_"&LOWER(G6)&"_fixed",Sheet5!$A$1:$T$1,0)) -> 45.4 | M6: =INDEX(Sheet5!$A$2:$Z$2,MATCH("fwd_"&LOWER(G6)&"_additional", Sheet5!$A$1:$Z$1, 0) ) -> 44.8 | N6: =L6+(K6*M6) -> 45.4 | O6: =INDEX( Sheet5!$A$2:$Z$2, MATCH("rto_"&LOWER(G6)&"_fixed", Sheet5!$A$1:$Z$1, 0) ) -> 41.3 | P6: =INDEX( Sheet5!$A$2:$Z$2, MATCH("rto_"&LOWER(G6)&"_additional", Sheet5!$A$1:$Z$1, 0) ) -> 44.8 | Q6: =O6+(K6*P6) -> 41.3 | R6: =N6+Q6 -> 86.7 | S6: =R6-I6 -> 41.3
A7: 2001806686 | B7: =_xlfn.XLOOKUP(A7,Sheet1!B:B,Sheet1!A:A) -> 1091117229555 | C7: {=SUMPRODUCT((Sheet2!$A$2:$A$1000=Sheet6!A7)*Sheet2!$C$2:$C$1000*IFERROR(VLOOKUP(Sheet2!$B$2:$B$1000,Sheet3!$A:$B,2,FALSE),0))/1000} -> 0.24 | D7: =CEILING(C7/0.5,1)*0.5 -> 0.5 | E7: =VLOOKUP(A7,Sheet1!B:C,2,FALSE) -> 0.15 | F7: =CEILING(E7/0.5,1)*0.5 -> 0.5 | G7: =VLOOKUP(Sheet4!B7,Sheet4!B:C,2,FALSE) -> d | H7: =VLOOKUP(A7,Sheet1!B:D,3,FALSE) -> 121003 | I7: =VLOOKUP(A7,Sheet1!B:H,7,FALSE) -> 45.4 | J7: =D7/0.5 -> 1 | K7: =MAX(J7-1,0) -> 0 | L7: =INDEX(Sheet5!$A$2:$T$2,MATCH("fwd_"&LOWER(G7)&"_fixed",Sheet5!$A$1:$T$1,0)) -> 45.4 | M7: =INDEX(Sheet5!$A$2:$Z$2,MATCH("fwd_"&LOWER(G7)&"_additional", Sheet5!$A$1:$Z$1, 0) ) -> 44.8 | N7: =L7+(K7*M7) -> 45.4 | O7: =INDEX( Sheet5!$A$2:$Z$2, MATCH("rto_"&LOWER(G7)&"_fixed", Sheet5!$A$1:$Z$1, 0) ) -> 41.3 | P7: =INDEX( Sheet5!$A$2:$Z$2, MATCH("rto_"&LOWER(G7)&"_additional", Sheet5!$A$1:$Z$1, 0) ) -> 44.8 | Q7: =O7+(K7*P7) -> 41.3 | R7: =N7+Q7 -> 86.7 | S7: =R7-I7 -> 41.3
A8: 2001806885 | B8: =_xlfn.XLOOKUP(A8,Sheet1!B:B,Sheet1!A:A) -> 1091117229776 | C8: {=SUMPRODUCT((Sheet2!$A$2:$A$1000=Sheet6!A8)*Sheet2!$C$2:$C$1000*IFERROR(VLOOKUP(Sheet2!$B$2:$B$1000,Sheet3!$A:$B,2,FALSE),0))/1000} -> 0.84 | D8: =CEILING(C8/0.5,1)*0.5 -> 1 | E8: =VLOOKUP(A8,Sheet1!B:C,2,FALSE) -> 1 | F8: =CEILING(E8/0.5,1)*0.5 -> 1 | G8: =VLOOKUP(Sheet4!B8,Sheet4!B:C,2,FALSE) -> b | H8: =VLOOKUP(A8,Sheet1!B:D,3,FALSE) -> 121003 | I8: =VLOOKUP(A8,Sheet1!B:H,7,FALSE) -> 61.3 | J8: =D8/0.5 -> 2 | K8: =MAX(J8-1,0) -> 1 | L8: =INDEX(Sheet5!$A$2:$T$2,MATCH("fwd_"&LOWER(G8)&"_fixed",Sheet5!$A$1:$T$1,0)) -> 33 | M8: =INDEX(Sheet5!$A$2:$Z$2,MATCH("fwd_"&LOWER(G8)&"_additional", Sheet5!$A$1:$Z$1, 0) ) -> 28.3 | N8: =L8+(K8*M8) -> 61.3 | O8: =INDEX( Sheet5!$A$2:$Z$2, MATCH("rto_"&LOWER(G8)&"_fixed", Sheet5!$A$1:$Z$1, 0) ) -> 20.5 | P8: =INDEX( Sheet5!$A$2:$Z$2, MATCH("rto_"&LOWER(G8)&"_additional", Sheet5!$A$1:$Z$1, 0) ) -> 28.3 | Q8: =O8+(K8*P8) -> 48.8 | R8: =N8+Q8 -> 110.1 | S8: =R8-I8 -> 48.8
A9: 2001807058 | B9: =_xlfn.XLOOKUP(A9,Sheet1!B:B,Sheet1!A:A) -> 1091117323112 | C9: {=SUMPRODUCT((Sheet2!$A$2:$A$1000=Sheet6!A9)*Sheet2!$C$2:$C$1000*IFERROR(VLOOKUP(Sheet2!$B$2:$B$1000,Sheet3!$A:$B,2,FALSE),0))/1000} -> 1.168 | D9: =CEILING(C9/0.5,1)*0.5 -> 1.5 | E9: =VLOOKUP(A9,Sheet1!B:C,2,FALSE) -> 1.15 | F9: =CEILING(E9/0.5,1)*0.5 -> 1.5 | G9: =VLOOKUP(Sheet4!B9,Sheet4!B:C,2,FALSE) -> b | H9: =VLOOKUP(A9,Sheet1!B:D,3,FALSE) -> 121003 | I9: =VLOOKUP(A9,Sheet1!B:H,7,FALSE) -> 89.6 | J9: =D9/0.5 -> 3 | K9: =MAX(J9-1,0) -> 2 | L9: =INDEX(Sheet5!$A$2:$T$2,MATCH("fwd_"&LOWER(G9)&"_fixed",Sheet5!$A$1:$T$1,0)) -> 33 | M9: =INDEX(Sheet5!$A$2:$Z$2,MATCH("fwd_"&LOWER(G9)&"_additional", Sheet5!$A$1:$Z$1, 0) ) -> 28.3 | N9: =L9+(K9*M9) -> 89.6 | O9: =INDEX( Sheet5!$A$2:$Z$2, MATCH("rto_"&LOWER(G9)&"_fixed", Sheet5!$A$1:$Z$1, 0) ) -> 20.5 | P9: =INDEX( Sheet5!$A$2:$Z$2, MATCH("rto_"&LOWER(G9)&"_additional", Sheet5!$A$1:$Z$1, 0) ) -> 28.3 | Q9: =O9+(K9*P9) -> 77.1 | R9: =N9+Q9 -> 166.7 | S9: =R9-I9 -> 77.1
A10: 2001807186 | B10: =_xlfn.XLOOKUP(A10,Sheet1!B:B,Sheet1!A:A) -> 1091117323812 | C10: {=SUMPRODUCT((Sheet2!$A$2:$A$1000=Sheet6!A10)*Sheet2!$C$2:$C$1000*IFERROR(VLOOKUP(Sheet2!$B$2:$B$1000,Sheet3!$A:$B,2,FALSE),0))/1000} -> 0.5 | D10: =CEILING(C10/0.5,1)*0.5 -> 0.5 | E10: =VLOOKUP(A10,Sheet1!B:C,2,FALSE) -> 0.5 | F10: =CEILING(E10/0.5,1)*0.5 -> 0.5 | G10: =VLOOKUP(Sheet4!B10,Sheet4!B:C,2,FALSE) -> d | H10: =VLOOKUP(A10,Sheet1!B:D,3,FALSE) -> 121003 | I10: =VLOOKUP(A10,Sheet1!B:H,7,FALSE) -> 45.4 | J10: =D10/0.5 -> 1 | K10: =MAX(J10-1,0) -> 0 | L10: =INDEX(Sheet5!$A$2:$T$2,MATCH("fwd_"&LOWER(G10)&"_fixed",Sheet5!$A$1:$T$1,0)) -> 45.4 | M10: =INDEX(Sheet5!$A$2:$Z$2,MATCH("fwd_"&LOWER(G10)&"_additional", Sheet5!$A$1:$Z$1, 0) ) -> 44.8 | N10: =L10+(K10*M10) -> 45.4 | O10: =INDEX( Sheet5!$A$2:$Z$2, MATCH("rto_"&LOWER(G10)&"_fixed", Sheet5!$A$1:$Z$1, 0) ) -> 41.3 | P10: =INDEX( Sheet5!$A$2:$Z$2, MATCH("rto_"&LOWER(G10)&"_additional", Sheet5!$A$1:$Z$1, 0) ) -> 44.8 | Q10: =O10+(K10*P10) -> 41.3 | R10: =N10+Q10 -> 86.7 | S10: =R10-I10 -> 41.3
A11: 2001807290 | B11: =_xlfn.XLOOKUP(A11,Sheet1!B:B,Sheet1!A:A) -> 1091117324206 | C11: {=SUMPRODUCT((Sheet2!$A$2:$A$1000=Sheet6!A11)*Sheet2!$C$2:$C$1000*IFERROR(VLOOKUP(Sheet2!$B$2:$B$1000,Sheet3!$A:$B,2,FALSE),0))/1000} -> 0.5 | D11: =CEILING(C11/0.5,1)*0.5 -> 0.5 | E11: =VLOOKUP(A11,Sheet1!B:C,2,FALSE) -> 0.5 | F11: =CEILING(E11/0.5,1)*0.5 -> 0.5 | G11: =VLOOKUP(Sheet4!B11,Sheet4!B:C,2,FALSE) -> d | H11: =VLOOKUP(A11,Sheet1!B:D,3,FALSE) -> 121003 | I11: =VLOOKUP(A11,Sheet1!B:H,7,FALSE) -> 45.4 | J11: =D11/0.5 -> 1 | K11: =MAX(J11-1,0) -> 0 | L11: =INDEX(Sheet5!$A$2:$T$2,MATCH("fwd_"&LOWER(G11)&"_fixed",Sheet5!$A$1:$T$1,0)) -> 45.4 | M11: =INDEX(Sheet5!$A$2:$Z$2,MATCH("fwd_"&LOWER(G11)&"_additional", Sheet5!$A$1:$Z$1, 0) ) -> 44.8 | N11: =L11+(K11*M11) -> 45.4 | O11: =INDEX( Sheet5!$A$2:$Z$2, MATCH("rto_"&LOWER(G11)&"_fixed", Sheet5!$A$1:$Z$1, 0) ) -> 41.3 | P11: =INDEX( Sheet5!$A$2:$Z$2, MATCH("rto_"&LOWER(G11)&"_additional", Sheet5!$A$1:$Z$1, 0) ) -> 44.8 | Q11: =O11+(K11*P11) -> 41.3 | R11: =N11+Q11 -> 86.7 | S11: =R11-I11 -> 41.3
A12: 2001807814 | B12: =_xlfn.XLOOKUP(A12,Sheet1!B:B,Sheet1!A:A) -> 1091117326612 | C12: {=SUMPRODUCT((Sheet2!$A$2:$A$1000=Sheet6!A12)*Sheet2!$C$2:$C$1000*IFERROR(VLOOKUP(Sheet2!$B$2:$B$1000,Sheet3!$A:$B,2,FALSE),0))/1000} -> 0.607 | D12: =CEILING(C12/0.5,1)*0.5 -> 1 | E12: =VLOOKUP(A12,Sheet1!B:C,2,FALSE) -> 0.79 | F12: =CEILING(E12/0.5,1)*0.5 -> 1 | G12: =VLOOKUP(Sheet4!B12,Sheet4!B:C,2,FALSE) -> b | H12: =VLOOKUP(A12,Sheet1!B:D,3,FALSE) -> 121003 | I12: =VLOOKUP(A12,Sheet1!B:H,7,FALSE) -> 61.3 | J12: =D12/0.5 -> 2 | K12: =MAX(J12-1,0) -> 1 | L12: =INDEX(Sheet5!$A$2:$T$2,MATCH("fwd_"&LOWER(G12)&"_fixed",Sheet5!$A$1:$T$1,0)) -> 33 | M12: =INDEX(Sheet5!$A$2:$Z$2,MATCH("fwd_"&LOWER(G12)&"_additional", Sheet5!$A$1:$Z$1, 0) ) -> 28.3 | N12: =L12+(K12*M12) -> 61.3 | O12: =INDEX( Sheet5!$A$2:$Z$2, MATCH("rto_"&LOWER(G12)&"_fixed", Sheet5!$A$1:$Z$1, 0) ) -> 20.5 | P12: =INDEX( Sheet5!$A$2:$Z$2, MATCH("rto_"&LOWER(G12)&"_additional", Sheet5!$A$1:$Z$1, 0) ) -> 28.3 | Q12: =O12+(K12*P12) -> 48.8 | R12: =N12+Q12 -> 110.1 | S12: =R12-I12 -> 48.8
A13: 2001807931 | B13: =_xlfn.XLOOKUP(A13,Sheet1!B:B,Sheet1!A:A) -> 1091117327172 | C13: {=SUMPRODUCT((Sheet2!$A$2:$A$1000=Sheet6!A13)*Sheet2!$C$2:$C$1000*IFERROR(VLOOKUP(Sheet2!$B$2:$B$1000,Sheet3!$A:$B,2,FALSE),0))/1000} -> 0.607 | D13: =CEILING(C13/0.5,1)*0.5 -> 1 | E13: =VLOOKUP(A13,Sheet1!B:C,2,FALSE) -> 0.72 | F13: =CEILING(E13/0.5,1)*0.5 -> 1 | G13: =VLOOKUP(Sheet4!B13,Sheet4!B:C,2,FALSE) -> d | H13: =VLOOKUP(A13,Sheet1!B:D,3,FALSE) -> 121003 | I13: =VLOOKUP(A13,Sheet1!B:H,7,FALSE) -> 90.2 | J13: =D13/0.5 -> 2 | K13: =MAX(J13-1,0) -> 1 | L13: =INDEX(Sheet5!$A$2:$T$2,MATCH("fwd_"&LOWER(G13)&"_fixed",Sheet5!$A$1:$T$1,0)) -> 45.4 | M13: =INDEX(Sheet5!$A$2:$Z$2,MATCH("fwd_"&LOWER(G13)&"_additional", Sheet5!$A$1:$Z$1, 0) ) -> 44.8 | N13: =L13+(K13*M13) -> 90.2 | O13: =INDEX( Sheet5!$A$2:$Z$2, MATCH("rto_"&LOWER(G13)&"_fixed", Sheet5!$A$1:$Z$1, 0) ) -> 41.3 | P13: =INDEX( Sheet5!$A$2:$Z$2, MATCH("rto_"&LOWER(G13)&"_additional", Sheet5!$A$1:$Z$1, 0) ) -> 44.8 | Q13: =O13+(K13*P13) -> 86.1 | R13: =N13+Q13 -> 176.3 | S13: =R13-I13 -> 86.1
... A125: 2001811305 | B125: =_xlfn.XLOOKUP(A125,Sheet1!B:B,Sheet1!A:A) -> 1091121846136 | C125: {=SUMPRODUCT((Sheet2!$A$2:$A$1000=Sheet6!A125)*Sheet2!$C$2:$C$1000*IFERROR(VLOOKUP(Sheet2!$B$2:$B$1000,Sheet3!$A:$B,2,FALSE),0))/1000} -> 0.75 | D125: =CEILING(C125/0.5,1)*0.5 -> 1 | E125: =VLOOKUP(A125,Sheet1!B:C,2,FALSE) -> 0.5 | F125: =CEILING(E125/0.5,1)*0.5 -> 0.5 | G125: =VLOOKUP(Sheet4!B125,Sheet4!B:C,2,FALSE) -> b | H125: =VLOOKUP(A125,Sheet1!B:D,3,FALSE) -> 121003 | I125: =VLOOKUP(A125,Sheet1!B:H,7,FALSE) -> 45.4 | J125: =D125/0.5 -> 2 | K125: =MAX(J125-1,0) -> 1 | L125: =INDEX(Sheet5!$A$2:$T$2,MATCH("fwd_"&LOWER(G125)&"_fixed",Sheet5!$A$1:$T$1,0)) -> 33 | M125: =INDEX(Sheet5!$A$2:$Z$2,MATCH("fwd_"&LOWER(G125)&"_additional", Sheet5!$A$1:$Z$1, 0) ) -> 28.3 | N125: =L125+(K125*M125) -> 61.3 | O125: =INDEX( Sheet5!$A$2:$Z$2, MATCH("rto_"&LOWER(G125)&"_fixed", Sheet5!$A$1:$Z$1, 0) ) -> 20.5 | P125: =INDEX( Sheet5!$A$2:$Z$2, MATCH("rto_"&LOWER(G125)&"_additional", Sheet5!$A$1:$Z$1, 0) ) -> 28.3 | Q125: =O125+(K125*P125) -> 48.8 | R125: =N125+Q125 -> 110.1 | S125: =R125-I125 -> 64.7

Sheet Summary
A1: Category | B1: Count | C1: Amount(Rs)
A2: Correctly Charged Orders | B2: =COUNTIF(Sheet6!S:S,0) -> 1 | C2: {=SUMPRODUCT((Sheet6!S2:S125=0)*(Sheet6!I2:I125))} -> 107.3
A3: Overcharged Orders | B3: =COUNTIF(Sheet6!S:S,">0") -> 75 | C3: =SUMIF(Sheet6!S:S,">0",Sheet6!S:S) -> 4372.5
A4: Undercharged Orders | B4: =COUNTIF(Sheet6!S:S,"<0") -> 48 | C4: =SUMIF(Sheet6!S:S,"<0",Sheet6!S:S) -> -2093.1
